<?xml version="1.0"?>
<robot name="cartpole">

    <!-- ########################   Robot   ##########################-->
    <!-- ########################   Robot   ##########################-->

  <link name="base">
    <visual>
      <geometry>
        <box size="0.2 0.25 0.2"/>
      </geometry>
      <material name="cart_mat">
        <color rgba="0.3 0.5 0.7 1"/>
      </material>
    </visual>
    <collision>
      <geometry>
          <box size="0.2 0.25 0.2"/>
      </geometry>
    </collision>
    <inertial>
      <mass value="1"/>
    </inertial>
  </link>

  <link name="link1">
    <visual>
      <geometry>
        <box size="0.1 0.1 0.6"/>	
      </geometry>
      <origin xyz="0 0 0.3"/>
      <material name="pole_mat">
        <color rgba="0.1 0.1 0.3 1"/>
      </material>
    </visual>
    <collision>
      <geometry>
        <box size="0.1 0.1 0.6"/>	
      </geometry>
      <origin xyz="0 0 0.3"/>
    </collision>
    <inertial>
      <mass value="1"/>
      <origin xyz="0 0 0.3"/>
    </inertial>
  </link>

  <link name="link2">
    <visual>
      <geometry>
        <box size="0.1 0.1 0.6"/>	
      </geometry>
      <origin xyz="0 0 0.3"/>
      <material name="pole_mat">
        <color rgba="0.1 0.1 0.3 1"/>
      </material>
    </visual>
    <collision>
      <geometry>
        <box size="0.1 0.1 0.6"/>	
      </geometry>
      <origin xyz="0 0 0.3"/>
    </collision>
    <inertial>
      <mass value="1"/>
      <origin xyz="0 0 0.3"/>
    </inertial>
  </link>

  <link name="ball_link">
    <visual>
      <origin xyz="0 3 0" rpy="0 0 0"/>
      <geometry>
        <sphere radius="0.1"/>
      </geometry>
      <material name="red">
        <color rgba="1 0 0 1"/>
      </material>
    </visual>
  </link>
  <!-- ########################   Box   ##########################-->
  <!-- ########################   Box   ##########################-->
  <!-- 첫 번째 박스 (왼쪽 벽) -->
  <link name="left_wall">
    <visual>
      <geometry>
        <box size="0.1 0.7 0.5"/>
      </geometry>
      <origin xyz="-0.35 3 0" rpy="0 0 0"/>
      <material name="gray">
        <color rgba="0.5 0.5 0.5 1.0"/>
      </material>
    </visual>
    <collision>
      <geometry>
        <box size="0.1 0.7 0.5"/>
      </geometry>
      <origin xyz="-0.35 3 0" rpy="0 0 0"/>
    </collision>
  </link>

  <!-- 두 번째 박스 (오른쪽 벽) -->
  <link name="right_wall">
    <visual>
      <geometry>
        <box size="0.1 0.7 0.5"/>
      </geometry>
      <origin xyz="0.35 3 0" rpy="0 0 0"/>
      <material name="gray">
        <color rgba="0.5 0.5 0.5 1.0"/>
      </material>
    </visual>
    <collision>
      <geometry>
        <box size="0.1 0.7 0.5"/>
      </geometry>
      <origin xyz="0.35 3 0" rpy="0 0 0"/>
    </collision>
  </link>

  <!-- 세 번째 박스 (앞쪽 벽) -->
  <link name="front_wall">
    <visual>
      <geometry>
        <box size="0.7 0.1 0.5"/>
      </geometry>
      <origin xyz="0 3.3 0" rpy="0 0 0"/>
      <material name="gray">
        <color rgba="0.5 0.5 0.5 1.0"/>
      </material>
    </visual>
    <collision>
      <geometry>
        <box size="0.7 0.1 0.5"/>
      </geometry>
      <origin xyz="0 3.3 0" rpy="0 0 0"/>
    </collision>
  </link>

  <!-- 네 번째 박스 (뒤쪽 벽) -->
  <link name="back_wall">
    <visual>
      <geometry>
        <box size="0.7 0.1 0.5"/>
      </geometry>
      <origin xyz="0 2.7 0" rpy="0 0 0"/>
      <material name="gray">
        <color rgba="0.5 0.5 0.5 1.0"/>
      </material>
    </visual>
    <collision>
      <geometry>
        <box size="0.7 0.1 0.5"/>
      </geometry>
      <origin xyz="0 2.7 0" rpy="0 0 0"/>
    </collision>
  </link>

  <!-- 5 번째 박스 (bottom) -->
  <link name="bottom_wall">
    <visual>
      <geometry>
        <box size="0.8 0.7 0.1"/>
      </geometry>
      <origin xyz="0 3 -0.25" rpy="0 0 0"/>
      <material name="gray">
        <color rgba="0.5 0.5 0.5 1.0"/>
      </material>
    </visual>
    <collision>
      <geometry>
        <box size="0.8 0.7 0.1"/>
      </geometry>
      <origin xyz="0 3 -0.25" rpy="0 0 0"/>
    </collision>
  </link>

  <!-- ########################   Joint   ##########################-->
  <!-- ########################   Joint   ##########################-->
  <joint name="base_to_link1" type="revolute">
    <parent link="base"/>
    <child link="link1"/>
    <origin xyz="0 0 0" rpy="3.14 0 0"/>
    <axis xyz="1 0 0"/>
    <limit lower="-0" upper="1.57" effort="100" velocity="10.0"/>
  </joint>

  <joint name="base_to_ball" type="fixed">
    <parent link="base"/>
    <child link="ball_link"/>
    <origin xyz="0 0 0" rpy="0 0 0"/>
  </joint>

  <joint name="link1_to_link2" type="revolute">
    <parent link="link1"/>
    <child link="link2"/>
    <origin xyz="0 0 0.6" rpy="0 0 0"/>
    <axis xyz="1 0 0"/>
    <limit lower="-0" upper="1.57" effort="100" velocity="10.0"/>
  </joint>

  <joint name="base_to_left_wall" type="fixed">
    <parent link="base"/>
    <child link="left_wall"/>
    <origin xyz="0 0 0" rpy="0 0 0"/>
  </joint>

  <joint name="left_wall_to_back_wall" type="fixed">
    <parent link="base"/>
    <child link="back_wall"/>
    <origin xyz="0 0 0" rpy="0 0 0"/>
  </joint>

  <joint name="back_wall_to_right_wall" type="fixed">
    <parent link="base"/>
    <child link="right_wall"/>
    <origin xyz="0 0 0" rpy="0 0 0"/>
  </joint>

  <joint name="right_wall_to_front_wall" type="fixed">
    <parent link="base"/>
    <child link="front_wall"/>
    <origin xyz="0 0 0" rpy="0 0 0"/>
  </joint>

  <joint name="base_to_bottom_wall" type="fixed">
    <parent link="base"/>
    <child link="bottom_wall"/>
    <origin xyz="0 0 0" rpy="0 0 0"/>
  </joint>


  
</robot>
